Workbook

Sheet Leeme
A1: CX ID 998 · Cambio de decodificador Android · Planilla de observación normalizada
A3: Fuente | B3: Planilla de observación en campo, pre-piloto La Plata (24 y 25 de septiembre). 27 visitas acompañadas (Lucas: V01-V16, Marcelo: V17-V27).
A4: Anonimización | B4: Se eliminaron nombres de clientes y ANI/teléfonos/direcciones. Cada visita se identifica como V01-V27. Los técnicos se identifican como Técnico A (V01-V16) y Técnico B (V17-V27).
A5: Base de análisis | B5: 25 recambios. Se excluyen de los conteos V07 y V15, registradas como 'Instalación' (no son recambios). Siguen visibles en los datos, sombreadas en gris.
A6: Criterios reformulados | B6: Los criterios redactados en negativo se pasaron a positivo, manteniendo las respuestas como estaban (decisión del equipo). Columna 'Criterio original' en la hoja Datos_normalizados.
A7: Alertas de polaridad | B7: Si una nota del observador contradice la lectura positiva, la fila queda en amarillo con una alerta. En esas filas, el conteo S/N no es confiable: usá las notas.
A8: Codificación | B8: Hoja Codificado: S (incluye 'S - ...' y 'Sí...'), N (incluye 'N - ...', 'No,...' y 'No explicó...'), N/A, Nota (observación textual sin S/N) y Sin registro (celda vacía).
A9: Hojas de validación | B9: Veredictos: veredicto, confianza, justificación, contraevidencia y reformulación de cada hipótesis, más las hipótesis emergentes y las reglas de decisión. Validación_hipótesis: evidencia por indicador en dos capas, Registrado (fórmulas sobre Codificado, total y por técnico) y Observado (notas de campo codificadas, con las visitas listadas).
A10: Hoja Resumen | B10: Conteos por criterio calculados con fórmulas sobre la hoja Codificado, solo para visitas con 'Base recambio = Sí'. Si corregís un código, el resumen se recalcula.
A11: Qué podés editar | B11: Hoja Codificado (códigos) y fila 2 de Codificado (inclusión en la base). No edites la hoja Resumen: son fórmulas.
A12: Otros ajustes | B12: V04 no tiene técnico, observador ni fecha registrados. En 'Consulta sobre aspectos de uso' la fila original tenía 28 valores: las consultas por control por voz se asignaron a V19 y V25, por consistencia con la fila 'Prueba del servicio'.

Sheet Validación_hipótesis
A1: Validación de hipótesis: evidencia registrada (planilla S/N, con fórmulas) y observada (notas de campo)
A2: Registrado: casos que confirman la predicción sobre los casos aplicables (se excluyen N/A y celdas sin registro), en la base de recambios. Observado: codificación manual de las notas; el n se calcula a partir de las visitas listadas. Los valores en azul del Técnico A/B son conteos manuales.
A4: Hip. | B4: Capa | C4: Indicador / evidencia | D4: Predicción si la hipótesis es cierta · visitas | E4: Confirma (n) | F4: Aplicables (n) | G4: % confirma | H4: Téc. A confirma | I4: Téc. A aplicables | J4: Téc. B confirma | K4: Téc. B aplicables | L4: Alerta de calidad
A5: H1. Existen momentos críticos dentro de la visita (llegada, explicación, instalación, prueba y cierre) que determinan la satisfacción final del cliente.
A6: H1 | B6: Registrado | C6: Prueba del servicio: el momento genera una reacción relevante del cliente | D6: Si H1 es cierta, el cliente reacciona (pregunta, se entusiasma, duda) al ver la nueva interfaz. [confirma: S, Nota] | E6: =COUNTIFS(Codificado!$E$6:$AE$6,"S",Codificado!$E$2:$AE$2,"Sí")+COUNTIFS(Codificado!$E$6:$AE$6,"Nota",Codificado!$E$2:$AE$2,"Sí") | F6: =COUNTIFS(Codificado!$E$6:$AE$6,"S",Codificado!$E$2:$AE$2,"Sí")+COUNTIFS(Codificado!$E$6:$AE$6,"Nota",Codificado!$E$2:$AE$2,"Sí")+COUNTIFS(Codificado!$E$6:$AE$6,"N",Codificado!$E$2:$AE$2,"Sí") | G6: =IFERROR(E6/F6,"-") | H6: =COUNTIFS(Codificado!$E$6:$T$6,"S",Codificado!$E$2:$T$2,"Sí")+COUNTIFS(Codificado!$E$6:$T$6,"Nota",Codificado!$E$2:$T$2,"Sí") | I6: =COUNTIFS(Codificado!$E$6:$T$6,"S",Codificado!$E$2:$T$2,"Sí")+COUNTIFS(Codificado!$E$6:$T$6,"Nota",Codificado!$E$2:$T$2,"Sí")+COUNTIFS(Codificado!$E$6:$T$6,"N",Codificado!$E$2:$T$2,"Sí") | J6: =COUNTIFS(Codificado!$U$6:$AE$6,"S",Codificado!$U$2:$AE$2,"Sí")+COUNTIFS(Codificado!$U$6:$AE$6,"Nota",Codificado!$U$2:$AE$2,"Sí") | K6: =COUNTIFS(Codificado!$U$6:$AE$6,"S",Codificado!$U$2:$AE$2,"Sí")+COUNTIFS(Codificado!$U$6:$AE$6,"Nota",Codificado!$U$2:$AE$2,"Sí")+COUNTIFS(Codificado!$U$6:$AE$6,"N",Codificado!$U$2:$AE$2,"Sí")
A7: H1 | B7: Registrado | C7: Explicación del cambio: el momento genera una reacción relevante del cliente | D7: El momento de la explicación genera reacción del cliente. [confirma: S, Nota] | E7: =COUNTIFS(Codificado!$E$4:$AE$4,"S",Codificado!$E$2:$AE$2,"Sí")+COUNTIFS(Codificado!$E$4:$AE$4,"Nota",Codificado!$E$2:$AE$2,"Sí") | F7: =COUNTIFS(Codificado!$E$4:$AE$4,"S",Codificado!$E$2:$AE$2,"Sí")+COUNTIFS(Codificado!$E$4:$AE$4,"Nota",Codificado!$E$2:$AE$2,"Sí")+COUNTIFS(Codificado!$E$4:$AE$4,"N",Codificado!$E$2:$AE$2,"Sí") | G7: =IFERROR(E7/F7,"-") | H7: =COUNTIFS(Codificado!$E$4:$T$4,"S",Codificado!$E$2:$T$2,"Sí")+COUNTIFS(Codificado!$E$4:$T$4,"Nota",Codificado!$E$2:$T$2,"Sí") | I7: =COUNTIFS(Codificado!$E$4:$T$4,"S",Codificado!$E$2:$T$2,"Sí")+COUNTIFS(Codificado!$E$4:$T$4,"Nota",Codificado!$E$2:$T$2,"Sí")+COUNTIFS(Codificado!$E$4:$T$4,"N",Codificado!$E$2:$T$2,"Sí") | J7: =COUNTIFS(Codificado!$U$4:$AE$4,"S",Codificado!$U$2:$AE$2,"Sí")+COUNTIFS(Codificado!$U$4:$AE$4,"Nota",Codificado!$U$2:$AE$2,"Sí") | K7: =COUNTIFS(Codificado!$U$4:$AE$4,"S",Codificado!$U$2:$AE$2,"Sí")+COUNTIFS(Codificado!$U$4:$AE$4,"Nota",Codificado!$U$2:$AE$2,"Sí")+COUNTIFS(Codificado!$U$4:$AE$4,"N",Codificado!$U$2:$AE$2,"Sí")
A8: H1 | B8: Registrado | C8: Instalación: el momento genera una reacción relevante del cliente | D8: La instalación genera reacción del cliente. [confirma: S, Nota] | E8: =COUNTIFS(Codificado!$E$5:$AE$5,"S",Codificado!$E$2:$AE$2,"Sí")+COUNTIFS(Codificado!$E$5:$AE$5,"Nota",Codificado!$E$2:$AE$2,"Sí") | F8: =COUNTIFS(Codificado!$E$5:$AE$5,"S",Codificado!$E$2:$AE$2,"Sí")+COUNTIFS(Codificado!$E$5:$AE$5,"Nota",Codificado!$E$2:$AE$2,"Sí")+COUNTIFS(Codificado!$E$5:$AE$5,"N",Codificado!$E$2:$AE$2,"Sí") | G8: =IFERROR(E8/F8,"-") | H8: =COUNTIFS(Codificado!$E$5:$T$5,"S",Codificado!$E$2:$T$2,"Sí")+COUNTIFS(Codificado!$E$5:$T$5,"Nota",Codificado!$E$2:$T$2,"Sí") | I8: =COUNTIFS(Codificado!$E$5:$T$5,"S",Codificado!$E$2:$T$2,"Sí")+COUNTIFS(Codificado!$E$5:$T$5,"Nota",Codificado!$E$2:$T$2,"Sí")+COUNTIFS(Codificado!$E$5:$T$5,"N",Codificado!$E$2:$T$2,"Sí") | J8: =COUNTIFS(Codificado!$U$5:$AE$5,"S",Codificado!$U$2:$AE$2,"Sí")+COUNTIFS(Codificado!$U$5:$AE$5,"Nota",Codificado!$U$2:$AE$2,"Sí") | K8: =COUNTIFS(Codificado!$U$5:$AE$5,"S",Codificado!$U$2:$AE$2,"Sí")+COUNTIFS(Codificado!$U$5:$AE$5,"Nota",Codificado!$U$2:$AE$2,"Sí")+COUNTIFS(Codificado!$U$5:$AE$5,"N",Codificado!$U$2:$AE$2,"Sí")
A9: H1 | B9: Registrado | C9: Cierre: el momento genera una reacción relevante del cliente | D9: El cierre genera reacción del cliente. [confirma: S, Nota] | E9: =COUNTIFS(Codificado!$E$7:$AE$7,"S",Codificado!$E$2:$AE$2,"Sí")+COUNTIFS(Codificado!$E$7:$AE$7,"Nota",Codificado!$E$2:$AE$2,"Sí") | F9: =COUNTIFS(Codificado!$E$7:$AE$7,"S",Codificado!$E$2:$AE$2,"Sí")+COUNTIFS(Codificado!$E$7:$AE$7,"Nota",Codificado!$E$2:$AE$2,"Sí")+COUNTIFS(Codificado!$E$7:$AE$7,"N",Codificado!$E$2:$AE$2,"Sí") | G9: =IFERROR(E9/F9,"-") | H9: =COUNTIFS(Codificado!$E$7:$T$7,"S",Codificado!$E$2:$T$2,"Sí")+COUNTIFS(Codificado!$E$7:$T$7,"Nota",Codificado!$E$2:$T$2,"Sí") | I9: =COUNTIFS(Codificado!$E$7:$T$7,"S",Codificado!$E$2:$T$2,"Sí")+COUNTIFS(Codificado!$E$7:$T$7,"Nota",Codificado!$E$2:$T$2,"Sí")+COUNTIFS(Codificado!$E$7:$T$7,"N",Codificado!$E$2:$T$2,"Sí") | J9: =COUNTIFS(Codificado!$U$7:$AE$7,"S",Codificado!$U$2:$AE$2,"Sí")+COUNTIFS(Codificado!$U$7:$AE$7,"Nota",Codificado!$U$2:$AE$2,"Sí") | K9: =COUNTIFS(Codificado!$U$7:$AE$7,"S",Codificado!$U$2:$AE$2,"Sí")+COUNTIFS(Codificado!$U$7:$AE$7,"Nota",Codificado!$U$2:$AE$2,"Sí")+COUNTIFS(Codificado!$U$7:$AE$7,"N",Codificado!$U$2:$AE$2,"Sí")
A10: H1 | B10: Registrado | C10: Llegada: el momento genera una reacción relevante del cliente (sorpresa, duda, emoción) | D10: La llegada genera reacción del cliente. [confirma: S, Nota] | E10: =COUNTIFS(Codificado!$E$3:$AE$3,"S",Codificado!$E$2:$AE$2,"Sí")+COUNTIFS(Codificado!$E$3:$AE$3,"Nota",Codificado!$E$2:$AE$2,"Sí") | F10: =COUNTIFS(Codificado!$E$3:$AE$3,"S",Codificado!$E$2:$AE$2,"Sí")+COUNTIFS(Codificado!$E$3:$AE$3,"Nota",Codificado!$E$2:$AE$2,"Sí")+COUNTIFS(Codificado!$E$3:$AE$3,"N",Codificado!$E$2:$AE$2,"Sí") | G10: =IFERROR(E10/F10,"-") | H10: =COUNTIFS(Codificado!$E$3:$T$3,"S",Codificado!$E$2:$T$2,"Sí")+COUNTIFS(Codificado!$E$3:$T$3,"Nota",Codificado!$E$2:$T$2,"Sí") | I10: =COUNTIFS(Codificado!$E$3:$T$3,"S",Codificado!$E$2:$T$2,"Sí")+COUNTIFS(Codificado!$E$3:$T$3,"Nota",Codificado!$E$2:$T$2,"Sí")+COUNTIFS(Codificado!$E$3:$T$3,"N",Codificado!$E$2:$T$2,"Sí") | J10: =COUNTIFS(Codificado!$U$3:$AE$3,"S",Codificado!$U$2:$AE$2,"Sí")+COUNTIFS(Codificado!$U$3:$AE$3,"Nota",Codificado!$U$2:$AE$2,"Sí") | K10: =COUNTIFS(Codificado!$U$3:$AE$3,"S",Codificado!$U$2:$AE$2,"Sí")+COUNTIFS(Codificado!$U$3:$AE$3,"Nota",Codificado!$U$2:$AE$2,"Sí")+COUNTIFS(Codificado!$U$3:$AE$3,"N",Codificado!$U$2:$AE$2,"Sí")
A11: H1 | B11: Observado | C11: Preguntas de uso en la prueba del servicio (HBO, Netflix, control, voz, apps) | D11: V10, V14, V16, V17, V25 | E11: =LEN(D11)-LEN(SUBSTITUTE(D11,"V","")) | F11: =COUNTIF(Codificado!$E$2:$AE$2,"Sí") | G11: =IFERROR(E11/F11,"-") | H11: 3 | I11: 14 | J11: 2 | K11: 11
A12: H1 | B12: Observado | C12: Expresiones de entusiasmo o satisfacción en la prueba o el cierre | D12: V01, V03, V08, V11, V16 | E12: =LEN(D12)-LEN(SUBSTITUTE(D12,"V","")) | F12: =COUNTIF(Codificado!$E$2:$AE$2,"Sí") | G12: =IFERROR(E12/F12,"-") | H12: 5 | I12: 14 | J12: 0 | K12: 11
A13: H1 | B13: Observado | C13: Notas de llegada: todas logísticas, ninguna emocional | D13: V06, V09, V13, V14, V23 | E13: =LEN(D13)-LEN(SUBSTITUTE(D13,"V","")) | F13: =COUNTIF(Codificado!$E$2:$AE$2,"Sí") | G13: =IFERROR(E13/F13,"-") | H13: 4 | I13: 14 | J13: 1 | K13: 11
A14: H2. La experiencia del cliente depende en gran medida de la capacidad del técnico para explicar beneficios, funcionamiento y pasos de la instalación.
A15: H2 | B15: Registrado | C15: Explicaciones claras, correctas y completas | D15: Si la experiencia depende del técnico y no hay guion, habrá brechas en la explicación proactiva (N = no explicó la Guía). [confirma: N] | E15: =COUNTIFS(Codificado!$E$10:$AE$10,"N",Codificado!$E$2:$AE$2,"Sí") | F15: =COUNTIFS(Codificado!$E$10:$AE$10,"N",Codificado!$E$2:$AE$2,"Sí")+COUNTIFS(Codificado!$E$10:$AE$10,"S",Codificado!$E$2:$AE$2,"Sí") | G15: =IFERROR(E15/F15,"-") | H15: =COUNTIFS(Codificado!$E$10:$T$10,"N",Codificado!$E$2:$T$2,"Sí") | I15: =COUNTIFS(Codificado!$E$10:$T$10,"N",Codificado!$E$2:$T$2,"Sí")+COUNTIFS(Codificado!$E$10:$T$10,"S",Codificado!$E$2:$T$2,"Sí") | J15: =COUNTIFS(Codificado!$U$10:$AE$10,"N",Codificado!$U$2:$AE$2,"Sí") | K15: =COUNTIFS(Codificado!$U$10:$AE$10,"N",Codificado!$U$2:$AE$2,"Sí")+COUNTIFS(Codificado!$U$10:$AE$10,"S",Codificado!$U$2:$AE$2,"Sí")
A16: H2 | B16: Registrado | C16: Ante preguntas: responde correctamente y de manera completa | D16: El técnico resuelve las dudas cuando el cliente pregunta. [confirma: S] | E16: =COUNTIFS(Codificado!$E$8:$AE$8,"S",Codificado!$E$2:$AE$2,"Sí") | F16: =COUNTIFS(Codificado!$E$8:$AE$8,"S",Codificado!$E$2:$AE$2,"Sí")+COUNTIFS(Codificado!$E$8:$AE$8,"N",Codificado!$E$2:$AE$2,"Sí") | G16: =IFERROR(E16/F16,"-") | H16: =COUNTIFS(Codificado!$E$8:$T$8,"S",Codificado!$E$2:$T$2,"Sí") | I16: =COUNTIFS(Codificado!$E$8:$T$8,"S",Codificado!$E$2:$T$2,"Sí")+COUNTIFS(Codificado!$E$8:$T$8,"N",Codificado!$E$2:$T$2,"Sí") | J16: =COUNTIFS(Codificado!$U$8:$AE$8,"S",Codificado!$U$2:$AE$2,"Sí") | K16: =COUNTIFS(Codificado!$U$8:$AE$8,"S",Codificado!$U$2:$AE$2,"Sí")+COUNTIFS(Codificado!$U$8:$AE$8,"N",Codificado!$U$2:$AE$2,"Sí")
A17: H2 | B17: Registrado | C17: Ante preguntas reiteradas sobre el mismo tema, reformula y adapta su lenguaje | D17: Ante preguntas reiteradas, el técnico adapta el lenguaje. [confirma: S] | E17: =COUNTIFS(Codificado!$E$9:$AE$9,"S",Codificado!$E$2:$AE$2,"Sí") | F17: =COUNTIFS(Codificado!$E$9:$AE$9,"S",Codificado!$E$2:$AE$2,"Sí")+COUNTIFS(Codificado!$E$9:$AE$9,"N",Codificado!$E$2:$AE$2,"Sí") | G17: =IFERROR(E17/F17,"-") | H17: =COUNTIFS(Codificado!$E$9:$T$9,"S",Codificado!$E$2:$T$2,"Sí") | I17: =COUNTIFS(Codificado!$E$9:$T$9,"S",Codificado!$E$2:$T$2,"Sí")+COUNTIFS(Codificado!$E$9:$T$9,"N",Codificado!$E$2:$T$2,"Sí") | J17: =COUNTIFS(Codificado!$U$9:$AE$9,"S",Codificado!$U$2:$AE$2,"Sí") | K17: =COUNTIFS(Codificado!$U$9:$AE$9,"S",Codificado!$U$2:$AE$2,"Sí")+COUNTIFS(Codificado!$U$9:$AE$9,"N",Codificado!$U$2:$AE$2,"Sí")
A18: H2 | B18: Registrado | C18: Demuestra empatía y contención | D18: El técnico demuestra empatía y contención. [confirma: S] | E18: =COUNTIFS(Codificado!$E$11:$AE$11,"S",Codificado!$E$2:$AE$2,"Sí") | F18: =COUNTIFS(Codificado!$E$11:$AE$11,"S",Codificado!$E$2:$AE$2,"Sí")+COUNTIFS(Codificado!$E$11:$AE$11,"N",Codificado!$E$2:$AE$2,"Sí") | G18: =IFERROR(E18/F18,"-") | H18: =COUNTIFS(Codificado!$E$11:$T$11,"S",Codificado!$E$2:$T$2,"Sí") | I18: =COUNTIFS(Codificado!$E$11:$T$11,"S",Codificado!$E$2:$T$2,"Sí")+COUNTIFS(Codificado!$E$11:$T$11,"N",Codificado!$E$2:$T$2,"Sí") | J18: =COUNTIFS(Codificado!$U$11:$AE$11,"S",Codificado!$U$2:$AE$2,"Sí") | K18: =COUNTIFS(Codificado!$U$11:$AE$11,"S",Codificado!$U$2:$AE$2,"Sí")+COUNTIFS(Codificado!$U$11:$AE$11,"N",Codificado!$U$2:$AE$2,"Sí")
A19: H2 | B19: Observado | C19: Dudas sobre elementos que no se explicaron (grilla, Home, accesos directos, vincular el control, voz) | D19: V06, V08, V14, V19, V25 | E19: =LEN(D19)-LEN(SUBSTITUTE(D19,"V","")) | F19: =COUNTIF(Codificado!$E$2:$AE$2,"Sí") | G19: =IFERROR(E19/F19,"-") | H19: 3 | I19: 14 | J19: 2 | K19: 11
A20: H2 | B20: Observado | C20: Visitas con explicación de Home / Guía / Menú | D20: V05, V09, V17 | E20: =LEN(D20)-LEN(SUBSTITUTE(D20,"V","")) | F20: =COUNTIF(Codificado!$E$2:$AE$2,"Sí") | G20: =IFERROR(E20/F20,"-") | H20: 2 | I20: 14 | J20: 1 | K20: 11
A21: H3. Existen barreras operativas y administrativas que afectan la fluidez de la instalación.
A22: H3 | B22: Registrado | C22: ¿El técnico necesitó reintentar la instalación? | D22: Si hay barreras operativas, el técnico tendrá que reintentar la instalación. [confirma: S] | E22: =COUNTIFS(Codificado!$E$12:$AE$12,"S",Codificado!$E$2:$AE$2,"Sí") | F22: =COUNTIFS(Codificado!$E$12:$AE$12,"S",Codificado!$E$2:$AE$2,"Sí")+COUNTIFS(Codificado!$E$12:$AE$12,"N",Codificado!$E$2:$AE$2,"Sí") | G22: =IFERROR(E22/F22,"-") | H22: =COUNTIFS(Codificado!$E$12:$T$12,"S",Codificado!$E$2:$T$2,"Sí") | I22: =COUNTIFS(Codificado!$E$12:$T$12,"S",Codificado!$E$2:$T$2,"Sí")+COUNTIFS(Codificado!$E$12:$T$12,"N",Codificado!$E$2:$T$2,"Sí") | J22: =COUNTIFS(Codificado!$U$12:$AE$12,"S",Codificado!$U$2:$AE$2,"Sí") | K22: =COUNTIFS(Codificado!$U$12:$AE$12,"S",Codificado!$U$2:$AE$2,"Sí")+COUNTIFS(Codificado!$U$12:$AE$12,"N",Codificado!$U$2:$AE$2,"Sí")
A23: H3 | B23: Registrado | C23: ¿El técnico necesitó pedir soporte técnico durante la visita? | D23: El técnico necesitará pedir soporte durante la visita. [confirma: S] | E23: =COUNTIFS(Codificado!$E$13:$AE$13,"S",Codificado!$E$2:$AE$2,"Sí") | F23: =COUNTIFS(Codificado!$E$13:$AE$13,"S",Codificado!$E$2:$AE$2,"Sí")+COUNTIFS(Codificado!$E$13:$AE$13,"N",Codificado!$E$2:$AE$2,"Sí") | G23: =IFERROR(E23/F23,"-") | H23: =COUNTIFS(Codificado!$E$13:$T$13,"S",Codificado!$E$2:$T$2,"Sí") | I23: =COUNTIFS(Codificado!$E$13:$T$13,"S",Codificado!$E$2:$T$2,"Sí")+COUNTIFS(Codificado!$E$13:$T$13,"N",Codificado!$E$2:$T$2,"Sí") | J23: =COUNTIFS(Codificado!$U$13:$AE$13,"S",Codificado!$U$2:$AE$2,"Sí") | K23: =COUNTIFS(Codificado!$U$13:$AE$13,"S",Codificado!$U$2:$AE$2,"Sí")+COUNTIFS(Codificado!$U$13:$AE$13,"N",Codificado!$U$2:$AE$2,"Sí")
A24: H3 | B24: Registrado | C24: ¿El dispositivo se reconoce inmediatamente? | D24: El dispositivo no se reconocerá de inmediato (N o nota de falla). [confirma: N, Nota] | E24: =COUNTIFS(Codificado!$E$16:$AE$16,"N",Codificado!$E$2:$AE$2,"Sí")+COUNTIFS(Codificado!$E$16:$AE$16,"Nota",Codificado!$E$2:$AE$2,"Sí") | F24: =COUNTIFS(Codificado!$E$16:$AE$16,"N",Codificado!$E$2:$AE$2,"Sí")+COUNTIFS(Codificado!$E$16:$AE$16,"Nota",Codificado!$E$2:$AE$2,"Sí")+COUNTIFS(Codificado!$E$16:$AE$16,"S",Codificado!$E$2:$AE$2,"Sí") | G24: =IFERROR(E24/F24,"-") | H24: =COUNTIFS(Codificado!$E$16:$T$16,"N",Codificado!$E$2:$T$2,"Sí")+COUNTIFS(Codificado!$E$16:$T$16,"Nota",Codificado!$E$2:$T$2,"Sí") | I24: =COUNTIFS(Codificado!$E$16:$T$16,"N",Codificado!$E$2:$T$2,"Sí")+COUNTIFS(Codificado!$E$16:$T$16,"Nota",Codificado!$E$2:$T$2,"Sí")+COUNTIFS(Codificado!$E$16:$T$16,"S",Codificado!$E$2:$T$2,"Sí") | J24: =COUNTIFS(Codificado!$U$16:$AE$16,"N",Codificado!$U$2:$AE$2,"Sí")+COUNTIFS(Codificado!$U$16:$AE$16,"Nota",Codificado!$U$2:$AE$2,"Sí") | K24: =COUNTIFS(Codificado!$U$16:$AE$16,"N",Codificado!$U$2:$AE$2,"Sí")+COUNTIFS(Codificado!$U$16:$AE$16,"Nota",Codificado!$U$2:$AE$2,"Sí")+COUNTIFS(Codificado!$U$16:$AE$16,"S",Codificado!$U$2:$AE$2,"Sí")
A25: H3 | B25: Registrado | C25: ¿El cliente reclama el reemplazo de decos no declarados? | D25: El cliente reclamará el reemplazo de decos no declarados. [confirma: S] | E25: =COUNTIFS(Codificado!$E$15:$AE$15,"S",Codificado!$E$2:$AE$2,"Sí") | F25: =COUNTIFS(Codificado!$E$15:$AE$15,"S",Codificado!$E$2:$AE$2,"Sí")+COUNTIFS(Codificado!$E$15:$AE$15,"N",Codificado!$E$2:$AE$2,"Sí") | G25: =IFERROR(E25/F25,"-") | H25: =COUNTIFS(Codificado!$E$15:$T$15,"S",Codificado!$E$2:$T$2,"Sí") | I25: =COUNTIFS(Codificado!$E$15:$T$15,"S",Codificado!$E$2:$T$2,"Sí")+COUNTIFS(Codificado!$E$15:$T$15,"N",Codificado!$E$2:$T$2,"Sí") | J25: =COUNTIFS(Codificado!$U$15:$AE$15,"S",Codificado!$U$2:$AE$2,"Sí") | K25: =COUNTIFS(Codificado!$U$15:$AE$15,"S",Codificado!$U$2:$AE$2,"Sí")+COUNTIFS(Codificado!$U$15:$AE$15,"N",Codificado!$U$2:$AE$2,"Sí")
A26: H3 | B26: Registrado | C26: Conciliación de los nuevos decos | D26: La conciliación no se completará. [confirma: N] | E26: =COUNTIFS(Codificado!$E$19:$AE$19,"N",Codificado!$E$2:$AE$2,"Sí") | F26: =COUNTIFS(Codificado!$E$19:$AE$19,"N",Codificado!$E$2:$AE$2,"Sí")+COUNTIFS(Codificado!$E$19:$AE$19,"S",Codificado!$E$2:$AE$2,"Sí") | G26: =IFERROR(E26/F26,"-") | H26: =COUNTIFS(Codificado!$E$19:$T$19,"N",Codificado!$E$2:$T$2,"Sí") | I26: =COUNTIFS(Codificado!$E$19:$T$19,"N",Codificado!$E$2:$T$2,"Sí")+COUNTIFS(Codificado!$E$19:$T$19,"S",Codificado!$E$2:$T$2,"Sí") | J26: =COUNTIFS(Codificado!$U$19:$AE$19,"N",Codificado!$U$2:$AE$2,"Sí") | K26: =COUNTIFS(Codificado!$U$19:$AE$19,"N",Codificado!$U$2:$AE$2,"Sí")+COUNTIFS(Codificado!$U$19:$AE$19,"S",Codificado!$U$2:$AE$2,"Sí")
A27: H3 | B27: Observado | C27: Discrepancia entre los decos del sistema y los del hogar | D27: V01, V05, V22 | E27: =LEN(D27)-LEN(SUBSTITUTE(D27,"V","")) | F27: =COUNTIF(Codificado!$E$2:$AE$2,"Sí") | G27: =IFERROR(E27/F27,"-") | H27: 2 | I27: 14 | J27: 1 | K27: 11
A28: H3 | B28: Observado | C28: HDMI o televisor que no funcionan (V27 figura S, con nota de HDMI) | D28: V03, V23, V27 | E28: =LEN(D28)-LEN(SUBSTITUTE(D28,"V","")) | F28: =COUNTIF(Codificado!$E$2:$AE$2,"Sí") | G28: =IFERROR(E28/F28,"-") | H28: 1 | I28: 14 | J28: 2 | K28: 11
A29: H3 | B29: Observado | C29: Conciliación completada en el viaje al siguiente cliente | D29: V19, V23 | E29: =LEN(D29)-LEN(SUBSTITUTE(D29,"V","")) | F29: =COUNTIF(Codificado!$E$2:$AE$2,"Sí") | G29: =IFERROR(E29/F29,"-") | H29: 0 | I29: 14 | J29: 2 | K29: 11
A30: H4. Parte de las fricciones no están asociadas al dispositivo, sino a limitaciones de gestión y registro (suscripciones, credenciales).
A31: H4 | B31: Registrado | C31: Las apps de terceros (Netflix/YouTube) se mantienen logueadas | D31: Las apps de terceros (Netflix, YouTube) no quedan logueadas después del cambio. [confirma: N] | E31: =COUNTIFS(Codificado!$E$23:$AE$23,"N",Codificado!$E$2:$AE$2,"Sí") | F31: =COUNTIFS(Codificado!$E$23:$AE$23,"N",Codificado!$E$2:$AE$2,"Sí")+COUNTIFS(Codificado!$E$23:$AE$23,"S",Codificado!$E$2:$AE$2,"Sí") | G31: =IFERROR(E31/F31,"-") | H31: =COUNTIFS(Codificado!$E$23:$T$23,"N",Codificado!$E$2:$T$2,"Sí") | I31: =COUNTIFS(Codificado!$E$23:$T$23,"N",Codificado!$E$2:$T$2,"Sí")+COUNTIFS(Codificado!$E$23:$T$23,"S",Codificado!$E$2:$T$2,"Sí") | J31: =COUNTIFS(Codificado!$U$23:$AE$23,"N",Codificado!$U$2:$AE$2,"Sí") | K31: =COUNTIFS(Codificado!$U$23:$AE$23,"N",Codificado!$U$2:$AE$2,"Sí")+COUNTIFS(Codificado!$U$23:$AE$23,"S",Codificado!$U$2:$AE$2,"Sí")
A32: H4 | B32: Registrado | C32: Las suscripciones previamente contratadas se mantienen activas | D32: Las suscripciones Movistar contratadas se pierden (alerta de polaridad). [confirma: N] | E32: =COUNTIFS(Codificado!$E$20:$AE$20,"N",Codificado!$E$2:$AE$2,"Sí") | F32: =COUNTIFS(Codificado!$E$20:$AE$20,"N",Codificado!$E$2:$AE$2,"Sí")+COUNTIFS(Codificado!$E$20:$AE$20,"S",Codificado!$E$2:$AE$2,"Sí") | G32: =IFERROR(E32/F32,"-") | H32: =COUNTIFS(Codificado!$E$20:$T$20,"N",Codificado!$E$2:$T$2,"Sí") | I32: =COUNTIFS(Codificado!$E$20:$T$20,"N",Codificado!$E$2:$T$2,"Sí")+COUNTIFS(Codificado!$E$20:$T$20,"S",Codificado!$E$2:$T$2,"Sí") | J32: =COUNTIFS(Codificado!$U$20:$AE$20,"N",Codificado!$U$2:$AE$2,"Sí") | K32: =COUNTIFS(Codificado!$U$20:$AE$20,"N",Codificado!$U$2:$AE$2,"Sí")+COUNTIFS(Codificado!$U$20:$AE$20,"S",Codificado!$U$2:$AE$2,"Sí") | L32: Polaridad a validar: leer con cautela
A33: H4 | B33: Registrado | C33: Las credenciales de las suscripciones se cargan automáticamente o el usuario las recuerda sin expresar disgusto | D33: Las credenciales no se cargan solas y el cliente no las recuerda (alerta de polaridad). [confirma: N] | E33: =COUNTIFS(Codificado!$E$22:$AE$22,"N",Codificado!$E$2:$AE$2,"Sí") | F33: =COUNTIFS(Codificado!$E$22:$AE$22,"N",Codificado!$E$2:$AE$2,"Sí")+COUNTIFS(Codificado!$E$22:$AE$22,"S",Codificado!$E$2:$AE$2,"Sí") | G33: =IFERROR(E33/F33,"-") | H33: =COUNTIFS(Codificado!$E$22:$T$22,"N",Codificado!$E$2:$T$2,"Sí") | I33: =COUNTIFS(Codificado!$E$22:$T$22,"N",Codificado!$E$2:$T$2,"Sí")+COUNTIFS(Codificado!$E$22:$T$22,"S",Codificado!$E$2:$T$2,"Sí") | J33: =COUNTIFS(Codificado!$U$22:$AE$22,"N",Codificado!$U$2:$AE$2,"Sí") | K33: =COUNTIFS(Codificado!$U$22:$AE$22,"N",Codificado!$U$2:$AE$2,"Sí")+COUNTIFS(Codificado!$U$22:$AE$22,"S",Codificado!$U$2:$AE$2,"Sí") | L33: Polaridad a validar: leer con cautela
A34: H4 | B34: Observado | C34: Fricción con apps de terceros o credenciales (sin sesión, modo visita, carga asistida) | D34: V05, V06, V09, V16, V22, V23, V25, V27 | E34: =LEN(D34)-LEN(SUBSTITUTE(D34,"V","")) | F34: =COUNTIF(Codificado!$E$2:$AE$2,"Sí") | G34: =IFERROR(E34/F34,"-") | H34: 4 | I34: 14 | J34: 4 | K34: 11
A35: H4 | B35: Observado | C35: Packs Movistar visibles después del cambio (fútbol) | D35: V04, V11, V13 | E35: =LEN(D35)-LEN(SUBSTITUTE(D35,"V","")) | F35: =COUNTIF(Codificado!$E$2:$AE$2,"Sí") | G35: =IFERROR(E35/F35,"-") | H35: 3 | I35: 14 | J35: 0 | K35: 11
A36: H4 | B36: Observado | C36: Delegación de la carga de apps en un familiar (hija, nieto) | D36: V05, V22 | E36: =LEN(D36)-LEN(SUBSTITUTE(D36,"V","")) | F36: =COUNTIF(Codificado!$E$2:$AE$2,"Sí") | G36: =IFERROR(E36/F36,"-") | H36: 1 | I36: 14 | J36: 1 | K36: 11
A37: H5. Existen consultas recurrentes que podrían resolverse previamente mediante comunicaciones o materiales explicativos.
A38: H5 | B38: Registrado | C38: Dudas que generan más tiempo de visita | D38: Habrá dudas que alargan la visita. [confirma: Nota] | E38: =COUNTIFS(Codificado!$E$24:$AE$24,"Nota",Codificado!$E$2:$AE$2,"Sí") | F38: =COUNTIFS(Codificado!$E$24:$AE$24,"Nota",Codificado!$E$2:$AE$2,"Sí")+COUNTIFS(Codificado!$E$24:$AE$24,"N",Codificado!$E$2:$AE$2,"Sí") | G38: =IFERROR(E38/F38,"-") | H38: =COUNTIFS(Codificado!$E$24:$T$24,"Nota",Codificado!$E$2:$T$2,"Sí") | I38: =COUNTIFS(Codificado!$E$24:$T$24,"Nota",Codificado!$E$2:$T$2,"Sí")+COUNTIFS(Codificado!$E$24:$T$24,"N",Codificado!$E$2:$T$2,"Sí") | J38: =COUNTIFS(Codificado!$U$24:$AE$24,"Nota",Codificado!$U$2:$AE$2,"Sí") | K38: =COUNTIFS(Codificado!$U$24:$AE$24,"Nota",Codificado!$U$2:$AE$2,"Sí")+COUNTIFS(Codificado!$U$24:$AE$24,"N",Codificado!$U$2:$AE$2,"Sí")
A39: H5 | B39: Registrado | C39: El cliente consulta sobre aspectos de uso (otra TV, control remoto, funciones de voz) | D39: El cliente consultará sobre el uso (control, apps, voz). [confirma: Nota] | E39: =COUNTIFS(Codificado!$E$27:$AE$27,"Nota",Codificado!$E$2:$AE$2,"Sí") | F39: =COUNTIFS(Codificado!$E$27:$AE$27,"Nota",Codificado!$E$2:$AE$2,"Sí")+COUNTIFS(Codificado!$E$27:$AE$27,"N",Codificado!$E$2:$AE$2,"Sí") | G39: =IFERROR(E39/F39,"-") | H39: =COUNTIFS(Codificado!$E$27:$T$27,"Nota",Codificado!$E$2:$T$2,"Sí") | I39: =COUNTIFS(Codificado!$E$27:$T$27,"Nota",Codificado!$E$2:$T$2,"Sí")+COUNTIFS(Codificado!$E$27:$T$27,"N",Codificado!$E$2:$T$2,"Sí") | J39: =COUNTIFS(Codificado!$U$27:$AE$27,"Nota",Codificado!$U$2:$AE$2,"Sí") | K39: =COUNTIFS(Codificado!$U$27:$AE$27,"Nota",Codificado!$U$2:$AE$2,"Sí")+COUNTIFS(Codificado!$U$27:$AE$27,"N",Codificado!$U$2:$AE$2,"Sí") | L39: Polaridad a validar: leer con cautela
A40: H5 | B40: Registrado | C40: El cliente consulta sobre otros temas ajenos a la gestión (facturación, débito, otra avería) | D40: El cliente consultará sobre temas ajenos al recambio. [confirma: Nota] | E40: =COUNTIFS(Codificado!$E$28:$AE$28,"Nota",Codificado!$E$2:$AE$2,"Sí") | F40: =COUNTIFS(Codificado!$E$28:$AE$28,"Nota",Codificado!$E$2:$AE$2,"Sí")+COUNTIFS(Codificado!$E$28:$AE$28,"N",Codificado!$E$2:$AE$2,"Sí") | G40: =IFERROR(E40/F40,"-") | H40: =COUNTIFS(Codificado!$E$28:$T$28,"Nota",Codificado!$E$2:$T$2,"Sí") | I40: =COUNTIFS(Codificado!$E$28:$T$28,"Nota",Codificado!$E$2:$T$2,"Sí")+COUNTIFS(Codificado!$E$28:$T$28,"N",Codificado!$E$2:$T$2,"Sí") | J40: =COUNTIFS(Codificado!$U$28:$AE$28,"Nota",Codificado!$U$2:$AE$2,"Sí") | K40: =COUNTIFS(Codificado!$U$28:$AE$28,"Nota",Codificado!$U$2:$AE$2,"Sí")+COUNTIFS(Codificado!$U$28:$AE$28,"N",Codificado!$U$2:$AE$2,"Sí")
A41: H5 | B41: Registrado | C41: El cliente reclama comunicación / información previa | D41: El cliente reclamará información previa. [confirma: Nota] | E41: =COUNTIFS(Codificado!$E$29:$AE$29,"Nota",Codificado!$E$2:$AE$2,"Sí") | F41: =COUNTIFS(Codificado!$E$29:$AE$29,"Nota",Codificado!$E$2:$AE$2,"Sí")+COUNTIFS(Codificado!$E$29:$AE$29,"N",Codificado!$E$2:$AE$2,"Sí") | G41: =IFERROR(E41/F41,"-") | H41: =COUNTIFS(Codificado!$E$29:$T$29,"Nota",Codificado!$E$2:$T$2,"Sí") | I41: =COUNTIFS(Codificado!$E$29:$T$29,"Nota",Codificado!$E$2:$T$2,"Sí")+COUNTIFS(Codificado!$E$29:$T$29,"N",Codificado!$E$2:$T$2,"Sí") | J41: =COUNTIFS(Codificado!$U$29:$AE$29,"Nota",Codificado!$U$2:$AE$2,"Sí") | K41: =COUNTIFS(Codificado!$U$29:$AE$29,"Nota",Codificado!$U$2:$AE$2,"Sí")+COUNTIFS(Codificado!$U$29:$AE$29,"N",Codificado!$U$2:$AE$2,"Sí")
...

Sheet Veredictos
A1: Hip. | B1: Enunciado original | C1: Veredicto | D1: Confianza | E1: Justificación (registrado + observado) | F1: Contraevidencia | G1: Reformulación propuesta | H1: Qué falta para cerrarla
A2: H1 | B2: Existen momentos críticos dentro de la visita (llegada, explicación, instalación, prueba y cierre) que determinan la satisfacción final del cliente. | C2: Parcial | D2: Media | E2: Hay dos momentos que concentran la reacción del cliente: la prueba del servicio y la explicación del motivo. La instalación no es un momento crítico. La parte causal de la hipótesis (que esos momentos determinan la satisfacción final) no se puede verificar sin NPS de la visita. | F2: La instalación no genera ninguna reacción y el cierre casi ninguna. No hay medición de satisfacción final (NPS/CSAT) en la visita, así que no se puede demostrar que estos momentos la determinen. En el Técnico B, el 11/11 de 'Explicación' está influido por la explicación en la puerta. | G2: La prueba del servicio y la explicación del motivo concentran las dudas y emociones del cliente durante la visita. | H2: Cruzar con el NPS/CSAT de la visita en el piloto para validar el vínculo con la satisfacción final.
A3: H2 | B3: La experiencia del cliente depende en gran medida de la capacidad del técnico para explicar beneficios, funcionamiento y pasos de la instalación. | C3: Validada | D3: Alta | E3: Los dos técnicos muestran el mismo patrón: responden bien cuando les preguntan, pero no explican de forma proactiva la Guía (22/25). Las dudas del cliente aparecen justo en lo que no se explica. El técnico es el único canal de aprendizaje del cliente. | F3: La capacidad reactiva del técnico es muy buena (25/25). La brecha no es de capacidad sino de proceso: la explicación depende de lo que pregunte el cliente. | G3: — | H3: Medir si la explicación de "los 5 botones" reduce los contactos por uso a 7 y 30 días.
A4: H3 | B4: Existen barreras operativas y administrativas que afectan la fluidez de la instalación. | C4: Parcial | D4: Alta | E4: Se refuta en lo técnico-operativo: el proceso de instalación es fluido en los dos técnicos. Se valida en lo registral y del hogar, con quiebres puntuales (inventario, HDMI, conciliación diferida) que a escala pueden generar órdenes que no cierran. | F4: No hubo reintentos ni llamadas a soporte, y el retiro de equipos, el perfil y la conciliación se completaron en los 25 recambios. | G4: Las barreras no están en la instalación, sino en la calidad del registro de equipos y en las condiciones del hogar. | H4: Medir el % de órdenes con discrepancia de inventario en el piloto.
A5: H4 | B5: Parte de las fricciones no están asociadas al dispositivo, sino a limitaciones de gestión y registro (suscripciones, credenciales). | C5: Validada | D5: Media | E5: Toda la fricción de continuidad está en las apps de terceros y en sus credenciales, no en el deco. La confianza es media porque las apps no se probaron en la mayoría de las visitas (17 a 19 N/A): 8/25 es un piso, no una tasa. | F5: Las suscripciones propias de Movistar (packs) se mantienen: no se registró ninguna pérdida. El hardware no generó fricción. | G5: — | H5: Agregar a la ficha del piloto un paso obligatorio: "probar Netflix y YouTube".
A6: H5 | B6: Existen consultas recurrentes que podrían resolverse previamente mediante comunicaciones o materiales explicativos. | C6: Validada | D6: Alta | E6: Hay un patrón recurrente y previsible en los dos técnicos: motivo del cambio (10/25), uso del control y apps, y pedidos ajenos. Todas son resolubles con comunicación previa y material de apoyo. | F6: Las consultas administrativas (costo, titularidad) son marginales: 1/25. | G6: — | H6: Medir en el piloto si el mensaje previo por WhatsApp reduce la pregunta por el motivo.
A7: H6 | B7: Los clientes llegan a la visita con bajo conocimiento sobre el motivo y alcance del cambio de deco. | C7: Parcial | D7: Baja | E7: El cliente sabe que habrá un cambio, pero no entiende para qué ni por qué. La confianza es baja: la explicación en la puerta (V17-V27) interviene sobre lo que se quería observar y dos criterios tienen alertas de polaridad. | F7: El contacto previo se recuerda (11/11 en el Técnico B) y nadie asumió otro alcance (0/24). El criterio "entiende el motivo" no se usa porque tiene la polaridad invertida en V17-V27. | G7: Los clientes saben que habrá un cambio, pero no comprenden el motivo ni el beneficio, y la información no llega a todos los miembros del hogar. | H7: Observar en el piloto sin explicar el motivo antes de registrar la reacción del cliente.
A8: H7 | B8: La nueva interfaz del SO y del control remoto genera dificultades de uso. | C8: No concluyente | D8: Baja | E8: Dentro de la visita no hay dificultades, pero el técnico maneja el control y 4 clientes ni lo tocaron. El uso autónomo ocurre después de la visita, donde la etnografía no llega. | F8: En la visita, el 100% ve el contenido y el perfil, y no se registraron errores. | G8: — | H8: Validar con la encuesta posterior (Qualtrics) y con los contactos por uso a 7 y 30 días.
A9: H8 | B9: La nueva interfaz del SO y del control remoto genera frustración en la adopción. | C9: Refutada | D9: Alta | E9: No hay señales de resistencia en 25/25 y no se registró ningún "antes era más fácil". La adopción emocional es positiva en los dos técnicos. | F9: Un solo caso (V05) concentra la inseguridad, la dependencia y las dudas sobre la interfaz. | G9: — | H9: Seguir el perfil del caso V05 (escéptico y dependiente de un familiar) en la encuesta.
A11: Id | B11: Hipótesis emergente (surgida en campo) | C11: Evidencia (n) | D11: Visitas | E11: Cómo validarla en el piloto
A12: E1 | B12: La visita técnica funciona como canal de soporte general del hogar (módem, wifi, deco adicional). | C12: =LEN(D12)-LEN(SUBSTITUTE(D12,"V","")) | D12: V03, V11, V13, V22 | E12: Protocolo de derivación. Medir en el piloto el % de visitas con pedidos ajenos.
A13: E2 | B13: La comunicación previa llega a quien atiende el contacto, no a quien recibe al técnico ni a quien usa la TV. | C13: =LEN(D13)-LEN(SUBSTITUTE(D13,"V","")) | D13: V01, V04, V09 | E13: Mensaje reenviable. Registrar en la ficha quién recibe al técnico.
A14: E3 | B14: Los clientes mayores delegan en un familiar la configuración de las apps, y eso posterga su uso. | C14: =LEN(D14)-LEN(SUBSTITUTE(D14,"V","")) | D14: V05, V22 | E14: Registrar el perfil y la dependencia. Preguntar en la encuesta si ya usa las apps.
A15: E4 | B15: El tiempo de visita escala con la cantidad de decos (1 deco ≈ 17 min; 3 decos ≈ 27 min). | C15: =LEN(D15)-LEN(SUBSTITUTE(D15,"V","")) | D15: V01, V11, V25 | E15: Validar con los tiempos del sistema para la planificación de la agenda.
B17: Regla de veredicto
A18: Validada | B18: La predicción se confirma en el registro y en lo observado, en los dos técnicos, sin contraevidencia relevante.
A19: Parcial | B19: La predicción se confirma en una parte de los indicadores y se contradice en otra, o se sostiene solo en un subconjunto de casos. Se propone reformularla.
A20: Refutada | B20: La predicción no se confirma en al menos el 80% de los casos aplicables, con registro y observación coincidentes.
A21: No concluyente | B21: El método de campo no permite observarla o el dato tiene problemas de polaridad o sesgo que impiden leerla.
A23: Alta | B23: Registro y observación coinciden, los dos técnicos muestran el mismo patrón y los criterios no tienen alertas de calidad.
A24: Media | B24: Hay coincidencia, pero con muchos N/A (el indicador no se relevó de forma sistemática) o con evidencia concentrada en un solo técnico.
A25: Baja | B25: Hay alertas de polaridad, sesgo de intervención del observador o el fenómeno ocurre fuera de la visita.

Sheet Resumen
A1: Hipótesis | B1: Criterio (redacción positiva) | C1: Alerta | D1: S | E1: N | F1: N/A | G1: Nota | H1: Sin registro | I1: Base | J1: % S sobre (S+N) | K1: Lectura
A2: H1 | B2: Llegada: el momento genera una reacción relevante del cliente (sorpresa, duda, emoción) | C2: No | D2: =COUNTIFS(Codificado!$E$3:$AE$3,"S",Codificado!$E$2:$AE$2,"Sí") | E2: =COUNTIFS(Codificado!$E$3:$AE$3,"N",Codificado!$E$2:$AE$2,"Sí") | F2: =COUNTIFS(Codificado!$E$3:$AE$3,"N/A",Codificado!$E$2:$AE$2,"Sí") | G2: =COUNTIFS(Codificado!$E$3:$AE$3,"Nota",Codificado!$E$2:$AE$2,"Sí") | H2: =COUNTIFS(Codificado!$E$3:$AE$3,"Sin registro",Codificado!$E$2:$AE$2,"Sí") | I2: =SUM(D2:H2) | J2: =IFERROR(D2/(D2+E2),"-")
A3: H1 | B3: Explicación del cambio: el momento genera una reacción relevante del cliente | C3: No | D3: =COUNTIFS(Codificado!$E$4:$AE$4,"S",Codificado!$E$2:$AE$2,"Sí") | E3: =COUNTIFS(Codificado!$E$4:$AE$4,"N",Codificado!$E$2:$AE$2,"Sí") | F3: =COUNTIFS(Codificado!$E$4:$AE$4,"N/A",Codificado!$E$2:$AE$2,"Sí") | G3: =COUNTIFS(Codificado!$E$4:$AE$4,"Nota",Codificado!$E$2:$AE$2,"Sí") | H3: =COUNTIFS(Codificado!$E$4:$AE$4,"Sin registro",Codificado!$E$2:$AE$2,"Sí") | I3: =SUM(D3:H3) | J3: =IFERROR(D3/(D3+E3),"-")
A4: H1 | B4: Instalación: el momento genera una reacción relevante del cliente | C4: No | D4: =COUNTIFS(Codificado!$E$5:$AE$5,"S",Codificado!$E$2:$AE$2,"Sí") | E4: =COUNTIFS(Codificado!$E$5:$AE$5,"N",Codificado!$E$2:$AE$2,"Sí") | F4: =COUNTIFS(Codificado!$E$5:$AE$5,"N/A",Codificado!$E$2:$AE$2,"Sí") | G4: =COUNTIFS(Codificado!$E$5:$AE$5,"Nota",Codificado!$E$2:$AE$2,"Sí") | H4: =COUNTIFS(Codificado!$E$5:$AE$5,"Sin registro",Codificado!$E$2:$AE$2,"Sí") | I4: =SUM(D4:H4) | J4: =IFERROR(D4/(D4+E4),"-")
A5: H1 | B5: Prueba del servicio: el momento genera una reacción relevante del cliente | C5: No | D5: =COUNTIFS(Codificado!$E$6:$AE$6,"S",Codificado!$E$2:$AE$2,"Sí") | E5: =COUNTIFS(Codificado!$E$6:$AE$6,"N",Codificado!$E$2:$AE$2,"Sí") | F5: =COUNTIFS(Codificado!$E$6:$AE$6,"N/A",Codificado!$E$2:$AE$2,"Sí") | G5: =COUNTIFS(Codificado!$E$6:$AE$6,"Nota",Codificado!$E$2:$AE$2,"Sí") | H5: =COUNTIFS(Codificado!$E$6:$AE$6,"Sin registro",Codificado!$E$2:$AE$2,"Sí") | I5: =SUM(D5:H5) | J5: =IFERROR(D5/(D5+E5),"-")
A6: H1 | B6: Cierre: el momento genera una reacción relevante del cliente | C6: No | D6: =COUNTIFS(Codificado!$E$7:$AE$7,"S",Codificado!$E$2:$AE$2,"Sí") | E6: =COUNTIFS(Codificado!$E$7:$AE$7,"N",Codificado!$E$2:$AE$2,"Sí") | F6: =COUNTIFS(Codificado!$E$7:$AE$7,"N/A",Codificado!$E$2:$AE$2,"Sí") | G6: =COUNTIFS(Codificado!$E$7:$AE$7,"Nota",Codificado!$E$2:$AE$2,"Sí") | H6: =COUNTIFS(Codificado!$E$7:$AE$7,"Sin registro",Codificado!$E$2:$AE$2,"Sí") | I6: =SUM(D6:H6) | J6: =IFERROR(D6/(D6+E6),"-")
A7: H2 | B7: Ante preguntas: responde correctamente y de manera completa | C7: No | D7: =COUNTIFS(Codificado!$E$8:$AE$8,"S",Codificado!$E$2:$AE$2,"Sí") | E7: =COUNTIFS(Codificado!$E$8:$AE$8,"N",Codificado!$E$2:$AE$2,"Sí") | F7: =COUNTIFS(Codificado!$E$8:$AE$8,"N/A",Codificado!$E$2:$AE$2,"Sí") | G7: =COUNTIFS(Codificado!$E$8:$AE$8,"Nota",Codificado!$E$2:$AE$2,"Sí") | H7: =COUNTIFS(Codificado!$E$8:$AE$8,"Sin registro",Codificado!$E$2:$AE$2,"Sí") | I7: =SUM(D7:H7) | J7: =IFERROR(D7/(D7+E7),"-")
A8: H2 | B8: Ante preguntas reiteradas sobre el mismo tema, reformula y adapta su lenguaje | C8: No | D8: =COUNTIFS(Codificado!$E$9:$AE$9,"S",Codificado!$E$2:$AE$2,"Sí") | E8: =COUNTIFS(Codificado!$E$9:$AE$9,"N",Codificado!$E$2:$AE$2,"Sí") | F8: =COUNTIFS(Codificado!$E$9:$AE$9,"N/A",Codificado!$E$2:$AE$2,"Sí") | G8: =COUNTIFS(Codificado!$E$9:$AE$9,"Nota",Codificado!$E$2:$AE$2,"Sí") | H8: =COUNTIFS(Codificado!$E$9:$AE$9,"Sin registro",Codificado!$E$2:$AE$2,"Sí") | I8: =SUM(D8:H8) | J8: =IFERROR(D8/(D8+E8),"-")
A9: H2 | B9: Explicaciones claras, correctas y completas | C9: No | D9: =COUNTIFS(Codificado!$E$10:$AE$10,"S",Codificado!$E$2:$AE$2,"Sí") | E9: =COUNTIFS(Codificado!$E$10:$AE$10,"N",Codificado!$E$2:$AE$2,"Sí") | F9: =COUNTIFS(Codificado!$E$10:$AE$10,"N/A",Codificado!$E$2:$AE$2,"Sí") | G9: =COUNTIFS(Codificado!$E$10:$AE$10,"Nota",Codificado!$E$2:$AE$2,"Sí") | H9: =COUNTIFS(Codificado!$E$10:$AE$10,"Sin registro",Codificado!$E$2:$AE$2,"Sí") | I9: =SUM(D9:H9) | J9: =IFERROR(D9/(D9+E9),"-")
A10: H2 | B10: Demuestra empatía y contención | C10: No | D10: =COUNTIFS(Codificado!$E$11:$AE$11,"S",Codificado!$E$2:$AE$2,"Sí") | E10: =COUNTIFS(Codificado!$E$11:$AE$11,"N",Codificado!$E$2:$AE$2,"Sí") | F10: =COUNTIFS(Codificado!$E$11:$AE$11,"N/A",Codificado!$E$2:$AE$2,"Sí") | G10: =COUNTIFS(Codificado!$E$11:$AE$11,"Nota",Codificado!$E$2:$AE$2,"Sí") | H10: =COUNTIFS(Codificado!$E$11:$AE$11,"Sin registro",Codificado!$E$2:$AE$2,"Sí") | I10: =SUM(D10:H10) | J10: =IFERROR(D10/(D10+E10),"-")
A11: H3 | B11: ¿El técnico necesitó reintentar la instalación? | C11: No | D11: =COUNTIFS(Codificado!$E$12:$AE$12,"S",Codificado!$E$2:$AE$2,"Sí") | E11: =COUNTIFS(Codificado!$E$12:$AE$12,"N",Codificado!$E$2:$AE$2,"Sí") | F11: =COUNTIFS(Codificado!$E$12:$AE$12,"N/A",Codificado!$E$2:$AE$2,"Sí") | G11: =COUNTIFS(Codificado!$E$12:$AE$12,"Nota",Codificado!$E$2:$AE$2,"Sí") | H11: =COUNTIFS(Codificado!$E$12:$AE$12,"Sin registro",Codificado!$E$2:$AE$2,"Sí") | I11: =SUM(D11:H11) | J11: =IFERROR(D11/(D11+E11),"-")
A12: H3 | B12: ¿El técnico necesitó pedir soporte técnico durante la visita? | C12: No | D12: =COUNTIFS(Codificado!$E$13:$AE$13,"S",Codificado!$E$2:$AE$2,"Sí") | E12: =COUNTIFS(Codificado!$E$13:$AE$13,"N",Codificado!$E$2:$AE$2,"Sí") | F12: =COUNTIFS(Codificado!$E$13:$AE$13,"N/A",Codificado!$E$2:$AE$2,"Sí") | G12: =COUNTIFS(Codificado!$E$13:$AE$13,"Nota",Codificado!$E$2:$AE$2,"Sí") | H12: =COUNTIFS(Codificado!$E$13:$AE$13,"Sin registro",Codificado!$E$2:$AE$2,"Sí") | I12: =SUM(D12:H12) | J12: =IFERROR(D12/(D12+E12),"-")
A13: H3 | B13: ¿El técnico necesitó gestionar aspectos administrativos durante la visita? | C13: No | D13: =COUNTIFS(Codificado!$E$14:$AE$14,"S",Codificado!$E$2:$AE$2,"Sí") | E13: =COUNTIFS(Codificado!$E$14:$AE$14,"N",Codificado!$E$2:$AE$2,"Sí") | F13: =COUNTIFS(Codificado!$E$14:$AE$14,"N/A",Codificado!$E$2:$AE$2,"Sí") | G13: =COUNTIFS(Codificado!$E$14:$AE$14,"Nota",Codificado!$E$2:$AE$2,"Sí") | H13: =COUNTIFS(Codificado!$E$14:$AE$14,"Sin registro",Codificado!$E$2:$AE$2,"Sí") | I13: =SUM(D13:H13) | J13: =IFERROR(D13/(D13+E13),"-")
A14: H3 | B14: ¿El cliente reclama el reemplazo de decos no declarados? | C14: No | D14: =COUNTIFS(Codificado!$E$15:$AE$15,"S",Codificado!$E$2:$AE$2,"Sí") | E14: =COUNTIFS(Codificado!$E$15:$AE$15,"N",Codificado!$E$2:$AE$2,"Sí") | F14: =COUNTIFS(Codificado!$E$15:$AE$15,"N/A",Codificado!$E$2:$AE$2,"Sí") | G14: =COUNTIFS(Codificado!$E$15:$AE$15,"Nota",Codificado!$E$2:$AE$2,"Sí") | H14: =COUNTIFS(Codificado!$E$15:$AE$15,"Sin registro",Codificado!$E$2:$AE$2,"Sí") | I14: =SUM(D14:H14) | J14: =IFERROR(D14/(D14+E14),"-")
A15: H3 | B15: ¿El dispositivo se reconoce inmediatamente? | C15: No | D15: =COUNTIFS(Codificado!$E$16:$AE$16,"S",Codificado!$E$2:$AE$2,"Sí") | E15: =COUNTIFS(Codificado!$E$16:$AE$16,"N",Codificado!$E$2:$AE$2,"Sí") | F15: =COUNTIFS(Codificado!$E$16:$AE$16,"N/A",Codificado!$E$2:$AE$2,"Sí") | G15: =COUNTIFS(Codificado!$E$16:$AE$16,"Nota",Codificado!$E$2:$AE$2,"Sí") | H15: =COUNTIFS(Codificado!$E$16:$AE$16,"Sin registro",Codificado!$E$2:$AE$2,"Sí") | I15: =SUM(D15:H15) | J15: =IFERROR(D15/(D15+E15),"-")
A16: H3 | B16: Llevarse los equipos viejos y firmar consentimiento | C16: No | D16: =COUNTIFS(Codificado!$E$17:$AE$17,"S",Codificado!$E$2:$AE$2,"Sí") | E16: =COUNTIFS(Codificado!$E$17:$AE$17,"N",Codificado!$E$2:$AE$2,"Sí") | F16: =COUNTIFS(Codificado!$E$17:$AE$17,"N/A",Codificado!$E$2:$AE$2,"Sí") | G16: =COUNTIFS(Codificado!$E$17:$AE$17,"Nota",Codificado!$E$2:$AE$2,"Sí") | H16: =COUNTIFS(Codificado!$E$17:$AE$17,"Sin registro",Codificado!$E$2:$AE$2,"Sí") | I16: =SUM(D16:H16) | J16: =IFERROR(D16/(D16+E16),"-")
A17: H3 | B17: Confirmar que el perfil del cliente quede activo | C17: No | D17: =COUNTIFS(Codificado!$E$18:$AE$18,"S",Codificado!$E$2:$AE$2,"Sí") | E17: =COUNTIFS(Codificado!$E$18:$AE$18,"N",Codificado!$E$2:$AE$2,"Sí") | F17: =COUNTIFS(Codificado!$E$18:$AE$18,"N/A",Codificado!$E$2:$AE$2,"Sí") | G17: =COUNTIFS(Codificado!$E$18:$AE$18,"Nota",Codificado!$E$2:$AE$2,"Sí") | H17: =COUNTIFS(Codificado!$E$18:$AE$18,"Sin registro",Codificado!$E$2:$AE$2,"Sí") | I17: =SUM(D17:H17) | J17: =IFERROR(D17/(D17+E17),"-")
A18: H3 | B18: Conciliación de los nuevos decos | C18: No | D18: =COUNTIFS(Codificado!$E$19:$AE$19,"S",Codificado!$E$2:$AE$2,"Sí") | E18: =COUNTIFS(Codificado!$E$19:$AE$19,"N",Codificado!$E$2:$AE$2,"Sí") | F18: =COUNTIFS(Codificado!$E$19:$AE$19,"N/A",Codificado!$E$2:$AE$2,"Sí") | G18: =COUNTIFS(Codificado!$E$19:$AE$19,"Nota",Codificado!$E$2:$AE$2,"Sí") | H18: =COUNTIFS(Codificado!$E$19:$AE$19,"Sin registro",Codificado!$E$2:$AE$2,"Sí") | I18: =SUM(D18:H18) | J18: =IFERROR(D18/(D18+E18),"-")
A19: H4 | B19: Las suscripciones previamente contratadas se mantienen activas | C19: Sí | D19: =COUNTIFS(Codificado!$E$20:$AE$20,"S",Codificado!$E$2:$AE$2,"Sí") | E19: =COUNTIFS(Codificado!$E$20:$AE$20,"N",Codificado!$E$2:$AE$2,"Sí") | F19: =COUNTIFS(Codificado!$E$20:$AE$20,"N/A",Codificado!$E$2:$AE$2,"Sí") | G19: =COUNTIFS(Codificado!$E$20:$AE$20,"Nota",Codificado!$E$2:$AE$2,"Sí") | H19: =COUNTIFS(Codificado!$E$20:$AE$20,"Sin registro",Codificado!$E$2:$AE$2,"Sí") | I19: =SUM(D19:H19) | J19: =IFERROR(D19/(D19+E19),"-") | K19: No usar % S/N: leer notas
A20: H4 | B20: Acceder a las suscripciones previamente contratadas implica un esfuerzo del cliente | C20: No | D20: =COUNTIFS(Codificado!$E$21:$AE$21,"S",Codificado!$E$2:$AE$2,"Sí") | E20: =COUNTIFS(Codificado!$E$21:$AE$21,"N",Codificado!$E$2:$AE$2,"Sí") | F20: =COUNTIFS(Codificado!$E$21:$AE$21,"N/A",Codificado!$E$2:$AE$2,"Sí") | G20: =COUNTIFS(Codificado!$E$21:$AE$21,"Nota",Codificado!$E$2:$AE$2,"Sí") | H20: =COUNTIFS(Codificado!$E$21:$AE$21,"Sin registro",Codificado!$E$2:$AE$2,"Sí") | I20: =SUM(D20:H20) | J20: =IFERROR(D20/(D20+E20),"-")
A21: H4 | B21: Las credenciales de las suscripciones se cargan automáticamente o el usuario las recuerda sin expresar disgusto | C21: Sí | D21: =COUNTIFS(Codificado!$E$22:$AE$22,"S",Codificado!$E$2:$AE$2,"Sí") | E21: =COUNTIFS(Codificado!$E$22:$AE$22,"N",Codificado!$E$2:$AE$2,"Sí") | F21: =COUNTIFS(Codificado!$E$22:$AE$22,"N/A",Codificado!$E$2:$AE$2,"Sí") | G21: =COUNTIFS(Codificado!$E$22:$AE$22,"Nota",Codificado!$E$2:$AE$2,"Sí") | H21: =COUNTIFS(Codificado!$E$22:$AE$22,"Sin registro",Codificado!$E$2:$AE$2,"Sí") | I21: =SUM(D21:H21) | J21: =IFERROR(D21/(D21+E21),"-") | K21: No usar % S/N: leer notas
A22: H4 | B22: Las apps de terceros (Netflix/YouTube) se mantienen logueadas | C22: No | D22: =COUNTIFS(Codificado!$E$23:$AE$23,"S",Codificado!$E$2:$AE$2,"Sí") | E22: =COUNTIFS(Codificado!$E$23:$AE$23,"N",Codificado!$E$2:$AE$2,"Sí") | F22: =COUNTIFS(Codificado!$E$23:$AE$23,"N/A",Codificado!$E$2:$AE$2,"Sí") | G22: =COUNTIFS(Codificado!$E$23:$AE$23,"Nota",Codificado!$E$2:$AE$2,"Sí") | H22: =COUNTIFS(Codificado!$E$23:$AE$23,"Sin registro",Codificado!$E$2:$AE$2,"Sí") | I22: =SUM(D22:H22) | J22: =IFERROR(D22/(D22+E22),"-")
A23: H5 | B23: Dudas que generan más tiempo de visita | C23: No | D23: =COUNTIFS(Codificado!$E$24:$AE$24,"S",Codificado!$E$2:$AE$2,"Sí") | E23: =COUNTIFS(Codificado!$E$24:$AE$24,"N",Codificado!$E$2:$AE$2,"Sí") | F23: =COUNTIFS(Codificado!$E$24:$AE$24,"N/A",Codificado!$E$2:$AE$2,"Sí") | G23: =COUNTIFS(Codificado!$E$24:$AE$24,"Nota",Codificado!$E$2:$AE$2,"Sí") | H23: =COUNTIFS(Codificado!$E$24:$AE$24,"Sin registro",Codificado!$E$2:$AE$2,"Sí") | I23: =SUM(D23:H23) | J23: =IFERROR(D23/(D23+E23),"-")
A24: H5 | B24: El cliente consulta sobre aspectos administrativos (costo, beneficio, titularidad) | C24: No | D24: =COUNTIFS(Codificado!$E$25:$AE$25,"S",Codificado!$E$2:$AE$2,"Sí") | E24: =COUNTIFS(Codificado!$E$25:$AE$25,"N",Codificado!$E$2:$AE$2,"Sí") | F24: =COUNTIFS(Codificado!$E$25:$AE$25,"N/A",Codificado!$E$2:$AE$2,"Sí") | G24: =COUNTIFS(Codificado!$E$25:$AE$25,"Nota",Codificado!$E$2:$AE$2,"Sí") | H24: =COUNTIFS(Codificado!$E$25:$AE$25,"Sin registro",Codificado!$E$2:$AE$2,"Sí") | I24: =SUM(D24:H24) | J24: =IFERROR(D24/(D24+E24),"-")
A25: H5 | B25: El cliente consulta sobre aspectos operativos (carga o baja de una suscripción) | C25: No | D25: =COUNTIFS(Codificado!$E$26:$AE$26,"S",Codificado!$E$2:$AE$2,"Sí") | E25: =COUNTIFS(Codificado!$E$26:$AE$26,"N",Codificado!$E$2:$AE$2,"Sí") | F25: =COUNTIFS(Codificado!$E$26:$AE$26,"N/A",Codificado!$E$2:$AE$2,"Sí") | G25: =COUNTIFS(Codificado!$E$26:$AE$26,"Nota",Codificado!$E$2:$AE$2,"Sí") | H25: =COUNTIFS(Codificado!$E$26:$AE$26,"Sin registro",Codificado!$E$2:$AE$2,"Sí") | I25: =SUM(D25:H25) | J25: =IFERROR(D25/(D25+E25),"-")
A26: H5 | B26: El cliente consulta sobre aspectos de uso (otra TV, control remoto, funciones de voz) | C26: Sí | D26: =COUNTIFS(Codificado!$E$27:$AE$27,"S",Codificado!$E$2:$AE$2,"Sí") | E26: =COUNTIFS(Codificado!$E$27:$AE$27,"N",Codificado!$E$2:$AE$2,"Sí") | F26: =COUNTIFS(Codificado!$E$27:$AE$27,"N/A",Codificado!$E$2:$AE$2,"Sí") | G26: =COUNTIFS(Codificado!$E$27:$AE$27,"Nota",Codificado!$E$2:$AE$2,"Sí") | H26: =COUNTIFS(Codificado!$E$27:$AE$27,"Sin registro",Codificado!$E$2:$AE$2,"Sí") | I26: =SUM(D26:H26) | J26: =IFERROR(D26/(D26+E26),"-") | K26: No usar % S/N: leer notas
A27: H5 | B27: El cliente consulta sobre otros temas ajenos a la gestión (facturación, débito, otra avería) | C27: No | D27: =COUNTIFS(Codificado!$E$28:$AE$28,"S",Codificado!$E$2:$AE$2,"Sí") | E27: =COUNTIFS(Codificado!$E$28:$AE$28,"N",Codificado!$E$2:$AE$2,"Sí") | F27: =COUNTIFS(Codificado!$E$28:$AE$28,"N/A",Codificado!$E$2:$AE$2,"Sí") | G27: =COUNTIFS(Codificado!$E$28:$AE$28,"Nota",Codificado!$E$2:$AE$2,"Sí") | H27: =COUNTIFS(Codificado!$E$28:$AE$28,"Sin registro",Codificado!$E$2:$AE$2,"Sí") | I27: =SUM(D27:H27) | J27: =IFERROR(D27/(D27+E27),"-")
A28: H5 | B28: El cliente reclama comunicación / información previa | C28: No | D28: =COUNTIFS(Codificado!$E$29:$AE$29,"S",Codificado!$E$2:$AE$2,"Sí") | E28: =COUNTIFS(Codificado!$E$29:$AE$29,"N",Codificado!$E$2:$AE$2,"Sí") | F28: =COUNTIFS(Codificado!$E$29:$AE$29,"N/A",Codificado!$E$2:$AE$2,"Sí") | G28: =COUNTIFS(Codificado!$E$29:$AE$29,"Nota",Codificado!$E$2:$AE$2,"Sí") | H28: =COUNTIFS(Codificado!$E$29:$AE$29,"Sin registro",Codificado!$E$2:$AE$2,"Sí") | I28: =SUM(D28:H28) | J28: =IFERROR(D28/(D28+E28),"-")
A29: H6 | B29: El cliente expresa haber recibido comunicación previa | C29: Sí | D29: =COUNTIFS(Codificado!$E$30:$AE$30,"S",Codificado!$E$2:$AE$2,"Sí") | E29: =COUNTIFS(Codificado!$E$30:$AE$30,"N",Codificado!$E$2:$AE$2,"Sí") | F29: =COUNTIFS(Codificado!$E$30:$AE$30,"N/A",Codificado!$E$2:$AE$2,"Sí") | G29: =COUNTIFS(Codificado!$E$30:$AE$30,"Nota",Codificado!$E$2:$AE$2,"Sí") | H29: =COUNTIFS(Codificado!$E$30:$AE$30,"Sin registro",Codificado!$E$2:$AE$2,"Sí") | I29: =SUM(D29:H29) | J29: =IFERROR(D29/(D29+E29),"-") | K29: No usar % S/N: leer notas
A30: H6 | B30: El cliente entiende el motivo por el que se realiza el cambio | C30: Sí | D30: =COUNTIFS(Codificado!$E$31:$AE$31,"S",Codificado!$E$2:$AE$2,"Sí") | E30: =COUNTIFS(Codificado!$E$31:$AE$31,"N",Codificado!$E$2:$AE$2,"Sí") | F30: =COUNTIFS(Codificado!$E$31:$AE$31,"N/A",Codificado!$E$2:$AE$2,"Sí") | G30: =COUNTIFS(Codificado!$E$31:$AE$31,"Nota",Codificado!$E$2:$AE$2,"Sí") | H30: =COUNTIFS(Codificado!$E$31:$AE$31,"Sin registro",Codificado!$E$2:$AE$2,"Sí") | I30: =SUM(D30:H30) | J30: =IFERROR(D30/(D30+E30),"-") | K30: No usar % S/N: leer notas
A31: H6 | B31: El cliente asume que el cambio tiene otro alcance (deco + control o solo deco) | C31: No | D31: =COUNTIFS(Codificado!$E$32:$AE$32,"S",Codificado!$E$2:$AE$2,"Sí") | E31: =COUNTIFS(Codificado!$E$32:$AE$32,"N",Codificado!$E$2:$AE$2,"Sí") | F31: =COUNTIFS(Codificado!$E$32:$AE$32,"N/A",Codificado!$E$2:$AE$2,"Sí") | G31: =COUNTIFS(Codificado!$E$32:$AE$32,"Nota",Codificado!$E$2:$AE$2,"Sí") | H31: =COUNTIFS(Codificado!$E$32:$AE$32,"Sin registro",Codificado!$E$2:$AE$2,"Sí") | I31: =SUM(D31:H31) | J31: =IFERROR(D31/(D31+E31),"-")
A32: H7 | B32: Tareas que generan más errores | C32: No | D32: =COUNTIFS(Codificado!$E$33:$AE$33,"S",Codificado!$E$2:$AE$2,"Sí") | E32: =COUNTIFS(Codificado!$E$33:$AE$33,"N",Codificado!$E$2:$AE$2,"Sí") | F32: =COUNTIFS(Codificado!$E$33:$AE$33,"N/A",Codificado!$E$2:$AE$2,"Sí") | G32: =COUNTIFS(Codificado!$E$33:$AE$33,"Nota",Codificado!$E$2:$AE$2,"Sí") | H32: =COUNTIFS(Codificado!$E$33:$AE$33,"Sin registro",Codificado!$E$2:$AE$2,"Sí") | I32: =SUM(D32:H32) | J32: =IFERROR(D32/(D32+E32),"-")
A33: H7 | B33: Botones más confusos | C33: No | D33: =COUNTIFS(Codificado!$E$34:$AE$34,"S",Codificado!$E$2:$AE$2,"Sí") | E33: =COUNTIFS(Codificado!$E$34:$AE$34,"N",Codificado!$E$2:$AE$2,"Sí") | F33: =COUNTIFS(Codificado!$E$34:$AE$34,"N/A",Codificado!$E$2:$AE$2,"Sí") | G33: =COUNTIFS(Codificado!$E$34:$AE$34,"Nota",Codificado!$E$2:$AE$2,"Sí") | H33: =COUNTIFS(Codificado!$E$34:$AE$34,"Sin registro",Codificado!$E$2:$AE$2,"Sí") | I33: =SUM(D33:H33) | J33: =IFERROR(D33/(D33+E33),"-")
A34: H7 | B34: Cantidad de asistencias necesarias | C34: No | D34: =COUNTIFS(Codificado!$E$35:$AE$35,"S",Codificado!$E$2:$AE$2,"Sí") | E34: =COUNTIFS(Codificado!$E$35:$AE$35,"N",Codificado!$E$2:$AE$2,"Sí") | F34: =COUNTIFS(Codificado!$E$35:$AE$35,"N/A",Codificado!$E$2:$AE$2,"Sí") | G34: =COUNTIFS(Codificado!$E$35:$AE$35,"Nota",Codificado!$E$2:$AE$2,"Sí") | H34: =COUNTIFS(Codificado!$E$35:$AE$35,"Sin registro",Codificado!$E$2:$AE$2,"Sí") | I34: =SUM(D34:H34) | J34: =IFERROR(D34/(D34+E34),"-")
A35: H7 | B35: El cliente reconoce las funcionalidades del control remoto | C35: Sí | D35: =COUNTIFS(Codificado!$E$36:$AE$36,"S",Codificado!$E$2:$AE$2,"Sí") | E35: =COUNTIFS(Codificado!$E$36:$AE$36,"N",Codificado!$E$2:$AE$2,"Sí") | F35: =COUNTIFS(Codificado!$E$36:$AE$36,"N/A",Codificado!$E$2:$AE$2,"Sí") | G35: =COUNTIFS(Codificado!$E$36:$AE$36,"Nota",Codificado!$E$2:$AE$2,"Sí") | H35: =COUNTIFS(Codificado!$E$36:$AE$36,"Sin registro",Codificado!$E$2:$AE$2,"Sí") | I35: =SUM(D35:H35) | J35: =IFERROR(D35/(D35+E35),"-") | K35: No usar % S/N: leer notas
A36: H7 | B36: El cliente logra ver el contenido | C36: No | D36: =COUNTIFS(Codificado!$E$37:$AE$37,"S",Codificado!$E$2:$AE$2,"Sí") | E36: =COUNTIFS(Codificado!$E$37:$AE$37,"N",Codificado!$E$2:$AE$2,"Sí") | F36: =COUNTIFS(Codificado!$E$37:$AE$37,"N/A",Codificado!$E$2:$AE$2,"Sí") | G36: =COUNTIFS(Codificado!$E$37:$AE$37,"Nota",Codificado!$E$2:$AE$2,"Sí") | H36: =COUNTIFS(Codificado!$E$37:$AE$37,"Sin registro",Codificado!$E$2:$AE$2,"Sí") | I36: =SUM(D36:H36) | J36: =IFERROR(D36/(D36+E36),"-")
A37: H7 | B37: El cliente logra ver las suscripciones | C37: Sí | D37: =COUNTIFS(Codificado!$E$38:$AE$38,"S",Codificado!$E$2:$AE$2,"Sí") | E37: =COUNTIFS(Codificado!$E$38:$AE$38,"N",Codificado!$E$2:$AE$2,"Sí") | F37: =COUNTIFS(Codificado!$E$38:$AE$38,"N/A",Codificado!$E$2:$AE$2,"Sí") | G37: =COUNTIFS(Codificado!$E$38:$AE$38,"Nota",Codificado!$E$2:$AE$2,"Sí") | H37: =COUNTIFS(Codificado!$E$38:$AE$38,"Sin registro",Codificado!$E$2:$AE$2,"Sí") | I37: =SUM(D37:H37) | J37: =IFERROR(D37/(D37+E37),"-") | K37: No usar % S/N: leer notas
A38: H7 | B38: El cliente logra ver datos de perfil | C38: No | D38: =COUNTIFS(Codificado!$E$39:$AE$39,"S",Codificado!$E$2:$AE$2,"Sí") | E38: =COUNTIFS(Codificado!$E$39:$AE$39,"N",Codificado!$E$2:$AE$2,"Sí") | F38: =COUNTIFS(Codificado!$E$39:$AE$39,"N/A",Codificado!$E$2:$AE$2,"Sí") | G38: =COUNTIFS(Codificado!$E$39:$AE$39,"Nota",Codificado!$E$2:$AE$2,"Sí") | H38: =COUNTIFS(Codificado!$E$39:$AE$39,"Sin registro",Codificado!$E$2:$AE$2,"Sí") | I38: =SUM(D38:H38) | J38: =IFERROR(D38/(D38+E38),"-")
A39: H8 | B39: Frases como "antes era más fácil" o "ahora es más fácil" | C39: No | D39: =COUNTIFS(Codificado!$E$40:$AE$40,"S",Codificado!$E$2:$AE$2,"Sí") | E39: =COUNTIFS(Codificado!$E$40:$AE$40,"N",Codificado!$E$2:$AE$2,"Sí") | F39: =COUNTIFS(Codificado!$E$40:$AE$40,"N/A",Codificado!$E$2:$AE$2,"Sí") | G39: =COUNTIFS(Codificado!$E$40:$AE$40,"Nota",Codificado!$E$2:$AE$2,"Sí") | H39: =COUNTIFS(Codificado!$E$40:$AE$40,"Sin registro",Codificado!$E$2:$AE$2,"Sí") | I39: =SUM(D39:H39) | J39: =IFERROR(D39/(D39+E39),"-")
A40: H8 | B40: Señales (gestos, muecas, expresiones) de resistencia al cambio | C40: No | D40: =COUNTIFS(Codificado!$E$41:$AE$41,"S",Codificado!$E$2:$AE$2,"Sí") | E40: =COUNTIFS(Codificado!$E$41:$AE$41,"N",Codificado!$E$2:$AE$2,"Sí") | F40: =COUNTIFS(Codificado!$E$41:$AE$41,"N/A",Codificado!$E$2:$AE$2,"Sí") | G40: =COUNTIFS(Codificado!$E$41:$AE$41,"Nota",Codificado!$E$2:$AE$2,"Sí") | H40: =COUNTIFS(Codificado!$E$41:$AE$41,"Sin registro",Codificado!$E$2:$AE$2,"Sí") | I40: =SUM(D40:H40) | J40: =IFERROR(D40/(D40+E40),"-")
...

Sheet Visitas
A1: ID | B1: Técnico | C1: Observador | D1: Fecha | E1: Tipo de TV | F1: Cant. decos | G1: Tipo de visita | H1: Base recambio | I1: Minutos en domicilio
A2: V01 | B2: Técnico A | C2: Lucas | D2: 24-sep | E2: LCD | F2: 3 | G2: Recambio | H2: Sí | I2: 25
A3: V02 | B3: Técnico A | C3: Lucas | D3: 24-sep | E3: LCD | F3: 1 | G3: Recambio | H3: Sí | I3: 15
A4: V03 | B4: Técnico A | C4: Lucas | D4: 24-sep | E4: LCD | F4: 1 | G4: Recambio | H4: Sí | I4: 20
A5: V04 | B5: Sin dato | C5: Sin dato | D5: Sin dato | E5: LCD | F5: 1 | G5: Recambio | H5: Sí | I5: 20
A6: V05 | B6: Técnico A | C6: Lucas | D6: 24-sep | E6: LCD | F6: 2 | G6: Recambio | H6: Sí | I6: 20
A7: V06 | B7: Técnico A | C7: Lucas | D7: 24-sep | E7: LCD | F7: 1 | G7: Recambio | H7: Sí | I7: 20
A8: V07 | B8: Técnico A | C8: Lucas | D8: 24-sep | E8: LCD | F8: 1 | G8: Instalación nueva | H8: No | I8: 15
A9: V08 | B9: Técnico A | C9: Lucas | D9: 24-sep | E9: LCD | F9: 1 | G9: Recambio | H9: Sí | I9: 20
A10: V09 | B10: Técnico A | C10: Lucas | D10: 25-sep | E10: LCD | F10: 1 | G10: Recambio | H10: Sí | I10: 15
A11: V10 | B11: Técnico A | C11: Lucas | D11: 25-sep | E11: LCD | F11: 2 | G11: Recambio | H11: Sí | I11: 20
A12: V11 | B12: Técnico A | C12: Lucas | D12: 25-sep | E12: LCD | F12: 3 | G12: Recambio | H12: Sí | I12: 30
A13: V12 | B13: Técnico A | C13: Lucas | D13: 25-sep | E13: LCD | F13: 1 | G13: Recambio | H13: Sí | I13: 15
... A28: V27 | B28: Técnico B | C28: Marcelo | D28: 25-sep | E28: LCD | F28: 1 | G28: Recambio | H28: Sí | I28: 15
G30: Visitas totales | I30: =COUNTA(A2:A28)
G31: Recambios (base) | I31: =COUNTIF(H2:H28,"Sí")
G32: Promedio minutos (base) | I32: =AVERAGEIFS(I2:I28,H2:H28,"Sí")
G33: Máximo minutos (base) | I33: =_xlfn.MAXIFS(I2:I28,H2:H28,"Sí")
G34: Mínimo minutos (base) | I34: =_xlfn.MINIFS(I2:I28,H2:H28,"Sí")
G35: Promedio minutos Técnico A | I35: =AVERAGEIFS(I2:I28,H2:H28,"Sí",B2:B28,"Técnico A")
G36: Promedio minutos Técnico B | I36: =AVERAGEIFS(I2:I28,H2:H28,"Sí",B2:B28,"Técnico B")
G37: Hogares con más de 1 deco (base) | I37: =COUNTIFS(F2:F28,">1",H2:H28,"Sí")
G38: Decos recambiados (base) | I38: =SUMIFS(F2:F28,H2:H28,"Sí")

Sheet Datos_normalizados
A1: Hipótesis | B1: Criterio original | C1: Criterio (redacción positiva) | D1: Alerta de lectura | E1: V01 | F1: V02 | G1: V03 | H1: V04 | I1: V05 | J1: V06 | K1: V07 | L1: V08 | M1: V09 | N1: V10 | O1: V11 | P1: V12 | Q1: V13 | R1: V14 | S1: V15 | T1: V16 | U1: V17 | V1: V18 | W1: V19 | X1: V20 | Y1: V21 | Z1: V22 | AA1: V23 | AB1: V24 | AC1: V25 | AD1: V26 | AE1: V27
A2: H1. Existen momentos críticos dentro de la visita (llegada, explicación, instalación, prueba y cierre) que determinan la satisfacción final del cliente.
A3: H1 | B3: Llegada | C3: Llegada: el momento genera una reacción relevante del cliente (sorpresa, duda, emoción) | E3: N | F3: N | G3: N | H3: N | J3: Estaba en la puerta esperándonos | K3: N | L3: N | M3: No es el titular | N3: N | O3: N | P3: N | Q3: Estaba en la puerta esperándonos | R3: Estaba almorzando | S3: N/A | T3: N | U3: N | V3: N | W3: N | X3: N | Y3: N | Z3: N | AA3: No esperó en la puerta | AB3: N | AC3: N | AD3: N | AE3: N
A4: H1 | B4: Explicación del cambio | C4: Explicación del cambio: el momento genera una reacción relevante del cliente | E4: N | F4: S | G4: ¿Por qué el cambio? | H4: S | J4: N | K4: N/A | L4: N | M4: N | N4: N | O4: "Ah, ¿puedo instalar apps?" | P4: "Ah, ¿es nuevo?" | Q4: N | R4: N | S4: N/A | T4: N | U4: S | V4: S | W4: S | X4: S | Y4: S | Z4: S | AA4: S | AB4: S | AC4: S | AD4: S | AE4: S
A5: H1 | B5: Instalación | C5: Instalación: el momento genera una reacción relevante del cliente | E5: N | F5: N | G5: N | H5: N | J5: N | K5: N | L5: N | M5: N | N5: N | O5: N | P5: N | Q5: N | R5: N | S5: N/A | T5: N | U5: N | V5: N | W5: N | X5: N | Y5: N | Z5: N | AA5: N | AB5: N | AC5: N | AD5: N | AE5: N
A6: H1 | B6: Prueba del servicio | C6: Prueba del servicio: el momento genera una reacción relevante del cliente | E6: S | F6: S | G6: S | H6: ¿Por qué el cambio? | J6: S | K6: S | L6: Entusiasmo | M6: S | N6: ¿Cómo veo HBO? | O6: Contento | P6: N | Q6: N | R6: ¿Cómo vincular el control del deco con el TV? | S6: N | T6: ¿Cómo vincular Netflix? | U6: S - Pregunta cómo usar las apps | V6: S | W6: S | X6: S | Y6: S | Z6: S | AA6: S | AB6: S | AC6: Consulta cómo se usa el control con la voz | AD6: S | AE6: S
A7: H1 | B7: Cierre | C7: Cierre: el momento genera una reacción relevante del cliente | E7: Animados / entusiasmados con el cambio | F7: N | G7: "Muy rápido el cambio" | H7: N | J7: N | K7: N | L7: N | M7: N | N7: N | O7: N | P7: N | Q7: N | R7: N | S7: N | T7: "Ustedes fueron muy amables..." | U7: N | V7: N | W7: N | X7: N | Y7: N | Z7: N | AA7: N | AB7: N | AC7: N | AD7: N | AE7: N
A8: H2. La experiencia del cliente depende en gran medida de la capacidad del técnico para explicar beneficios, funcionamiento y pasos de la instalación.
